#VRML_SIM R2020b utf8
WorldInfo {
  coordinateSystem "NUE"
}
Viewpoint {
  orientation 9.056708932252189e-05 -0.993661375966696 -0.11241468636070034 3.080383290572862
  position -1.1827279580165015 -0.10796752387419728 -5.118582028578579
}
Background {
  skyColor [
    0.784314 0.898039 0.921569
  ]
  backUrl [
    "textures/cubic/dusk_back.png"
  ]
  bottomUrl [
    "textures/cubic/dusk_bottom.png"
  ]
  frontUrl [
    "textures/cubic/dusk_front.png"
  ]
  leftUrl [
    "textures/cubic/dusk_left.png"
  ]
  rightUrl [
    "textures/cubic/dusk_right.png"
  ]
  topUrl [
    "textures/cubic/dusk_top.png"
  ]
  backIrradianceUrl [
    "textures/cubic/dusk_back.hdr"
  ]
  bottomIrradianceUrl [
    "textures/cubic/dusk_bottom.hdr"
  ]
  frontIrradianceUrl [
    "textures/cubic/dusk_front.hdr"
  ]
  leftIrradianceUrl [
    "textures/cubic/dusk_left.hdr"
  ]
  rightIrradianceUrl [
    "textures/cubic/dusk_right.hdr"
  ]
  topIrradianceUrl [
    "textures/cubic/dusk_top.hdr"
  ]
}
UnevenTerrain {
  translation 0 -2.53 0
  name "uneven terrain(1)"
  size 10 2 10
  xDimension 200
  zDimension 200
  randomSeed 6
  perlinNOctaves 9
}
CircleArena {
  translation 0 -1.2 0
  radius 5
}
DEF ROBOT Robot {
  translation 0.13500288800476962 -0.8622333114085935 -0.039940920704766104
  rotation -6.458600961108045e-05 0.999999719718207 0.0007459169890770264 -0.4815949216841737
  children [
    DEF GPS GPS {
      name "GPS"
    }
    DEF IMU InertialUnit {
    }
    DEF EMITTER Emitter {
    }
    DEF RECEIVER Receiver {
    }
    DEF body_hip1_a HingeJoint {
      jointParameters HingeJointParameters {
        position 0.08727479584734715
        axis 0 1 0
        anchor -0.06 -0.06 0
        minStop -0.5
        maxStop 0.5
      }
      device [
        DEF hipx_a_pos_sensor PositionSensor {
          name "hipx_a_pos_sensor"
        }
        DEF h1a RotationalMotor {
          name "hipx_a"
          minPosition -3.102793096529908e-12
          maxPosition 0.08724432505309414
        }
      ]
      endPoint Solid {
        translation -0.06003105214057366 -0.06003878288456278 -1.6812855741334785e-05
        rotation 0.04358198260888584 0.043582528801986 0.9980987796681763 1.5726920162601923
        children [
          DEF hip1_hip2a HingeJoint {
            jointParameters HingeJointParameters {
              position 0.4500728070856622
              axis 0 0 1
              minStop 0.45
              maxStop 0.78
            }
            device [
              DEF hipy_a_pos_sensor PositionSensor {
                name "hipy_a_pos_sensor"
              }
              DEF h2a RotationalMotor {
                name "hipy_a"
                maxTorque 25
              }
            ]
            endPoint Solid {
              translation -0.06532517045097558 0.13522003519984346 0.025038318366501628
              rotation 0.00011081627885426917 0.0009332289246151099 0.9999995584016659 0.45006978066268644
              children [
                DEF leg1_leg2 HingeJoint {
                  jointParameters HingeJointParameters {
                    position 0.1532611000433322
                    axis 0 0 1
                    anchor 0 0.135 0
                    minStop 0.15
                    maxStop 0.78
                  }
                  device [
                    DEF leg_a_pos_sensor PositionSensor {
                      name "leg_a_pos_sensor"
                    }
                    RotationalMotor {
                      name "leg_a"
                    }
                  ]
                  endPoint Solid {
                    translation -0.019082726692974058 0.25853481105324605 -0.025399999999999916
                    rotation 0 0 1 0.1532611000433335
                    children [
                      Shape {
                        appearance Appearance {
                          material Material {
                            diffuseColor 1 0.219608 0.92549
                            emissiveColor 0.666667 0 0.498039
                          }
                        }
                        geometry DEF leg2 Box {
                          size 0.0254 0.26 0.0254
                        }
                      }
                    ]
                    name "leg2"
                    boundingObject USE leg2
                    physics Physics {
                    }
                    linearVelocity 0.00010118400844023756 0.00015862448213110723 3.861913255960997e-05
                    angularVelocity -0.00022596899378751365 0.0004297136688024292 0.001438312867683861
                  }
                }
                Shape {
                  appearance Appearance {
                    material Material {
                      diffuseColor 0.333333 0.333333 0.498039
                      emissiveColor 0.815686 0.0431373 0.117647
                    }
                  }
                  geometry DEF leg1 Box {
                    size 0.0254 0.31 0.0254
                  }
                }
              ]
              name "hip2a"
              boundingObject USE leg1
              physics Physics {
              }
              linearVelocity 2.9928286290212337e-05 0.0003000386837523304 -2.5687660777817628e-05
              angularVelocity 0.00030094864667802416 0.00043338960777253624 0.00016405490269428852
            }
          }
          Shape {
            appearance Appearance {
              material Material {
                diffuseColor 0.333333 0.666667 1
                emissiveColor 0.313725 0.666667 1
              }
            }
            geometry DEF servoMount1 Box {
              size 0.0254 0.0254 0.0254
            }
          }
        ]
        name "hip1a"
        boundingObject USE servoMount1
        physics Physics {
          mass 1
        }
        linearVelocity 2.47621545522634e-05 0.00031356727726409894 -4.496863931291274e-05
        angularVelocity 0.00029565337950592316 0.00044299231411085757 0.00016185874281394628
      }
    }
    DEF body_hip1_b HingeJoint {
      jointParameters HingeJointParameters {
        position 0.04879789149442445
        axis 0 1 0
        anchor 0.06 -0.06 0
        minStop -0.5
        maxStop 0.5
      }
      device [
        DEF hipx_b_pos_sensor PositionSensor {
          name "hipx_b_pos_sensor"
        }
        DEF h1b RotationalMotor {
          name "hipx_b"
          maxPosition 2
        }
      ]
      endPoint Solid {
        translation 0.06 -0.06 0
        rotation 0.7070024497930929 0.7070005422746205 -0.017255990552787932 3.176093559625641
        children [
          DEF hip1_hip2 HingeJoint {
            jointParameters HingeJointParameters {
              position 0.44995354549903566
              axis 0 0 1
              minStop 0.45
              maxStop 0.78
            }
            device [
              DEF hipy_b_pos_sensor PositionSensor {
                name "hipy_b_pos_sensor"
              }
              DEF h2 RotationalMotor {
                name "hipy_b"
              }
            ]
            endPoint Solid {
              translation -0.06523855557316921 0.1350700961231852 0.02499999999999996
              rotation 0 0 1 0.4499535454990356
              children [
                DEF leg1_leg2 HingeJoint {
                  jointParameters HingeJointParameters {
                    position 0.15271779525985787
                    axis 0 0 1
                    anchor 0 0.135 0
                    minStop 0.15
                    maxStop 2
                  }
                  device [
                    DEF leg_b_pos_sensor PositionSensor {
                      name "leg_b_pos_sensor"
                    }
                    RotationalMotor {
                      name "leg_b"
                      minPosition -1.0373917653557153e-05
                      maxPosition 2
                    }
                  ]
                  endPoint Solid {
                    translation -0.019015606826084802 0.25854516055692245 -0.025399999999999985
                    rotation 0 0 1 0.15271779525985685
                    children [
                      Shape {
                        appearance Appearance {
                          material Material {
                            diffuseColor 1 0.219608 0.92549
                            emissiveColor 0.666667 0 0.498039
                          }
                        }
                        geometry DEF leg2 Box {
                          size 0.0254 0.26 0.0254
                        }
                      }
                    ]
                    name "leg2"
                    boundingObject USE leg2
                    physics Physics {
                    }
                    linearVelocity -8.96523296664258e-05 0.00016603154373348418 -3.052135461681043e-05
                    angularVelocity 0.0009166240490604449 -0.0001820465761056499 -0.0012281303355249013
                  }
                }
                Shape {
                  appearance Appearance {
                    material Material {
                      diffuseColor 0.333333 0.333333 0.498039
                      emissiveColor 0.815686 0.0431373 0.117647
                    }
                  }
                  geometry DEF leg1 Box {
                    size 0.0254 0.31 0.0254
                  }
                }
              ]
              name "hip2"
              boundingObject USE leg1
              physics Physics {
              }
              linearVelocity 1.6272949635180946e-05 0.0003255992323042017 -1.1209358757142279e-06
              angularVelocity 0.0002803260251488058 -0.00017828204851270068 0.00015612234482726014
            }
          }
          Shape {
            appearance Appearance {
              material Material {
                diffuseColor 0.333333 0.666667 1
                emissiveColor 0.313725 0.666667 1
              }
            }
            geometry DEF servoMount1 Box {
              size 0.0254 0.0254 0.0254
            }
          }
        ]
        name "hip1(1)"
        boundingObject USE servoMount1
        physics Physics {
          mass 1
        }
        linearVelocity 1.9029888255772643e-05 0.0003144559748660643 -2.3844212446476837e-05
        angularVelocity 0.0002852394589110229 -0.00016979991049677579 0.00015786516346944602
      }
    }
    DEF body_hip1_c HingeJoint {
      jointParameters HingeJointParameters {
        position -0.10602822101311314
        axis 0 1 0
        anchor 0 0.06 0.06
        minStop -0.5
        maxStop 0.5
      }
      device [
        DEF hipx_c_pos_sensor PositionSensor {
          name "hipx_c_pos_sensor"
        }
        DEF h1c RotationalMotor {
          name "hipx_c"
          minPosition -0.10598925615820445
        }
      ]
      endPoint Solid {
        translation -4.416003779872834e-08 -0.06000059999999975 0.060000029879262624
        rotation 0.5558405002643467 0.5558361780609218 0.6181322523736388 2.034295079673536
        children [
          DEF hip1_hip2 HingeJoint {
            jointParameters HingeJointParameters {
              position 0.4500408812944605
              axis 0 0 1
            }
            device [
              DEF hipy_c_pos_sensor PositionSensor {
                name "hipy_c_pos_sensor"
              }
              DEF h2 RotationalMotor {
                name "hipy_c"
                maxTorque 25
              }
            ]
            endPoint Solid {
              translation -0.06525035177863239 0.1350643979469228 0.024999999999999967
              rotation 0 0 0.9999999999999999 0.45004088129446007
              children [
                DEF leg1_leg2 HingeJoint {
                  jointParameters HingeJointParameters {
                    position 0.15333284470438113
                    axis 0 0 1
                    anchor 0 0.135 0
                    minStop 0.15
                    maxStop 0.78
                  }
                  device [
                    DEF leg_c_pos_sensor PositionSensor {
                      name "leg_c_pos_sensor"
                    }
                    RotationalMotor {
                      name "leg_c"
                      minPosition -1.0374070713654395e-05
                      maxPosition 2
                    }
                  ]
                  endPoint Solid {
                    translation -0.019091589607000997 0.25853344165155356 -0.0253999999999999
                    rotation 0 0 1 0.15333284470438224
                    children [
                      Shape {
                        appearance Appearance {
                          material Material {
                            diffuseColor 1 0.219608 0.92549
                            emissiveColor 0.666667 0 0.498039
                          }
                        }
                        geometry DEF leg2 Box {
                          size 0.0254 0.26 0.0254
                        }
                      }
                    ]
                    name "leg2"
                    boundingObject USE leg2
                    physics Physics {
                    }
                    linearVelocity 7.677220879906399e-05 9.497839768628947e-05 -0.00014295250703302923
                    angularVelocity 0.0009472476778975541 -0.00022721408719638238 0.00061770437010422
                  }
                }
                Shape {
                  appearance Appearance {
                    material Material {
                      diffuseColor 0.333333 0.333333 0.498039
                      emissiveColor 0.815686 0.0431373 0.117647
                    }
                  }
                  geometry DEF leg1 Box {
                    size 0.0254 0.31 0.0254
                  }
                }
              ]
              name "hip2"
              boundingObject USE leg1
              physics Physics {
              }
              linearVelocity 4.583133417876954e-05 0.0002505617951629476 -3.7140687894167504e-05
              angularVelocity 0.00028201363365532874 -0.00023093134087984147 0.00017089016272776327
            }
          }
          Shape {
            appearance Appearance {
              material Material {
                diffuseColor 0.333333 0.666667 1
                emissiveColor 0.313725 0.666667 1
              }
            }
            geometry DEF servoMount1 Box {
              size 0.0254 0.0254 0.0254
            }
          }
        ]
        name "hip1(2)"
        boundingObject USE servoMount1
        physics Physics {
          mass 1
        }
        linearVelocity 4.711328424059502e-05 0.0002948479123033961 -1.750774087440732e-05
        angularVelocity 0.00028529731538963645 -0.00024010428071151972 0.00016631629630037715
      }
    }
    DEF body_hip1_d HingeJoint {
      jointParameters HingeJointParameters {
        position -0.016211617327294096
        axis 0 1 0
        anchor 0 -0.06 -0.06
        minStop -0.5
        maxStop 0.5
      }
      device [
        DEF hipx_d_pos_sensor PositionSensor {
          name "hipx_d_pos_sensor"
        }
        DEF h1d RotationalMotor {
          name "hipx_d"
        }
      ]
      endPoint Solid {
        translation -2.0011836773030027e-13 -0.0600006 -0.060000000000003245
        rotation -0.5804476503647489 -0.5804436709348049 0.5711091577428699 2.1037802201460147
        children [
          DEF hip1_hip2 HingeJoint {
            jointParameters HingeJointParameters {
              position 0.4500387301641028
              axis 0 0 1
              minStop 0.45
              maxStop 0.78
            }
            device [
              DEF hipy_d_pos_sensor PositionSensor {
                name "hipy_d_pos_sensor"
              }
              DEF h2 RotationalMotor {
                name "hipy_d"
                maxTorque 25
              }
            ]
            endPoint Solid {
              translation -0.0652500612373547 0.13506453830862275 0.024999999999999988
              rotation 0 0 1 0.4500387301641023
              children [
                DEF leg1_leg2 HingeJoint {
                  jointParameters HingeJointParameters {
                    position 0.15307216431344098
                    axis 0 0 1
                    anchor 0 0.135 0
                    minStop 0.15
                    maxStop 0.78
                  }
                  device [
                    DEF leg_d_pos_sensor PositionSensor {
                      name "leg_d_pos_sensor"
                    }
                    DEF leg_d RotationalMotor {
                      name "leg_d"
                    }
                  ]
                  endPoint Solid {
                    translation -0.01905938621282438 0.25853841425722784 -0.025399999999999978
                    rotation 0 0 1 0.15307216431344045
                    children [
                      Shape {
                        appearance Appearance {
                          material Material {
                            diffuseColor 1 0.219608 0.92549
                            emissiveColor 0.666667 0 0.498039
                          }
                        }
                        geometry DEF leg2 Box {
                          size 0.0254 0.26 0.0254
                        }
                      }
                    ]
                    name "leg2"
                    boundingObject USE leg2
                    physics Physics {
                    }
                    linearVelocity -4.1383364896243565e-05 0.00019960016213723436 5.799038460141157e-05
                    angularVelocity -0.00187840621677378 -0.00015244616761756662 -0.0010340923304796162
                  }
                }
                Shape {
                  appearance Appearance {
                    material Material {
                      diffuseColor 0.333333 0.333333 0.498039
                      emissiveColor 0.815686 0.0431373 0.117647
                    }
                  }
                  geometry DEF leg1 Box {
                    size 0.0254 0.31 0.0254
                  }
                }
              ]
              name "hip2"
              boundingObject USE leg1
              physics Physics {
              }
              linearVelocity 1.1072319217794283e-05 0.00037987947937045627 -6.85850454523097e-05
              angularVelocity 0.0002950918181112522 -0.0001573132472475484 0.00015040531657817182
            }
          }
          Shape {
            appearance Appearance {
              material Material {
                diffuseColor 0.333333 0.666667 1
                emissiveColor 0.313725 0.666667 1
              }
            }
            geometry DEF servoMount1 Box {
              size 0.0254 0.0254 0.0254
            }
          }
        ]
        name "hip1(3)"
        boundingObject USE servoMount1
        physics Physics {
          mass 1
        }
        linearVelocity -2.5786644396248476e-06 0.00033447031512110945 -4.6718409816094216e-05
        angularVelocity 0.0002928705789922453 -0.00016621210314225675 0.00015527022932732622
      }
    }
    DEF body Shape {
      appearance Appearance {
        material Material {
          ambientIntensity 0.3
          diffuseColor 1 1 0
          emissiveColor 1 0.666667 0
          shininess 1
        }
      }
      geometry Capsule {
        height 0.1
        radius 0.05
      }
    }
  ]
  name "chris"
  boundingObject USE body
  physics Physics {
    mass 1
  }
  controller "protocol2_controller"
  linearVelocity 1.2296267006428624e-05 0.00031429715378618545 -1.599115166648789e-05
  angularVelocity 0.0002901626182958934 0.00014584090708148284 0.00015984641196158865
}
