#VRML_SIM R2020b utf8
WorldInfo {
  basicTimeStep 8
  coordinateSystem "NUE"
}
Viewpoint {
  orientation 0.148245475395345 0.987792256575604 0.04785119511657438 6.052917090175646
  position -0.37931904723808174 -1.1185783187438658 1.7165006050361553
}
Background {
  skyColor [
    0.784314 0.898039 0.921569
  ]
  backUrl [
    "textures/cubic/dusk_back.png"
  ]
  bottomUrl [
    "textures/cubic/dusk_bottom.png"
  ]
  frontUrl [
    "textures/cubic/dusk_front.png"
  ]
  leftUrl [
    "textures/cubic/dusk_left.png"
  ]
  rightUrl [
    "textures/cubic/dusk_right.png"
  ]
  topUrl [
    "textures/cubic/dusk_top.png"
  ]
  backIrradianceUrl [
    "textures/cubic/dusk_back.hdr"
  ]
  bottomIrradianceUrl [
    "textures/cubic/dusk_bottom.hdr"
  ]
  frontIrradianceUrl [
    "textures/cubic/dusk_front.hdr"
  ]
  leftIrradianceUrl [
    "textures/cubic/dusk_left.hdr"
  ]
  rightIrradianceUrl [
    "textures/cubic/dusk_right.hdr"
  ]
  topIrradianceUrl [
    "textures/cubic/dusk_top.hdr"
  ]
}
UnevenTerrain {
  translation 0 -2.53 0
  name "uneven terrain(1)"
  size 10 2 10
  xDimension 200
  zDimension 200
  randomSeed 6
  perlinNOctaves 9
}
CircleArena {
  translation 0 -1.2 0
  radius 5
}
DEF ROBOT Robot {
  translation 0.17538816888644101 -0.8940578872075117 -0.0384549302787656
  rotation -0.0001802954965678322 0.999999521369723 0.0009616412318613284 -0.3725958470813845
  children [
    DEF GPS GPS {
      name "GPS"
    }
    DEF IMU InertialUnit {
    }
    DEF EMITTER Emitter {
    }
    DEF RECEIVER Receiver {
    }
    DEF body_hip1_a HingeJoint {
      jointParameters HingeJointParameters {
        position 6.2490825602159225e-06
        axis 0 1 0
        anchor -0.06 -0.06 0
        minStop -0.5
        maxStop 0.5
      }
      device [
        DEF hipx_a_pos_sensor PositionSensor {
          name "hipx_a_pos_sensor"
        }
        DEF h1a RotationalMotor {
          name "hipx_a"
          minPosition -3.102793096529908e-12
          maxPosition 0.08727479584734715
        }
      ]
      endPoint Solid {
        translation -0.060029468600326014 -0.06003878288456278 -1.945531154237056e-05
        rotation 3.0066836837505514e-06 3.233034117723034e-06 0.9999999999902536 1.5707889775782575
        children [
          DEF hip1_hip2a HingeJoint {
            jointParameters HingeJointParameters {
              position 0.450019514361457
              axis 0 0 1
            }
            device [
              DEF hipy_a_pos_sensor PositionSensor {
                name "hipy_a_pos_sensor"
              }
              DEF h2a RotationalMotor {
                name "hipy_a"
                maxTorque 25
              }
            ]
            endPoint Solid {
              translation -0.06531796411417048 0.13522351636411403 0.025038318366501593
              rotation 0.00011085404821857928 0.0009333346017854521 0.9999995582988531 0.45001648796205945
              children [
                DEF leg1_leg2 HingeJoint {
                  jointParameters HingeJointParameters {
                    position -3.1601395675817656e-06
                    axis 0 0 1
                    anchor 0 0.135 0
                  }
                  device [
                    DEF leg_a_pos_sensor PositionSensor {
                      name "leg_a_pos_sensor"
                    }
                    RotationalMotor {
                      name "leg_a"
                    }
                  ]
                  endPoint Solid {
                    translation 3.950174459470625e-07 0.2599999999993756 -0.025399999999999905
                    rotation 0 0 -0.9999999999999999 3.1601705889255862e-06
                    children [
                      Shape {
                        appearance Appearance {
                          material Material {
                            diffuseColor 1 0.219608 0.92549
                            emissiveColor 0.666667 0 0.498039
                          }
                        }
                        geometry DEF leg2 Box {
                          size 0.0254 0.26 0.0254
                        }
                      }
                    ]
                    name "leg2"
                    boundingObject USE leg2
                    physics Physics {
                    }
                    linearVelocity 2.6679630544035584e-06 -2.545999498162745e-05 -7.4940625946439335e-06
                    angularVelocity -5.328313965066935e-05 3.1485197229904e-05 0.0001559574709962347
                  }
                }
                Shape {
                  appearance Appearance {
                    material Material {
                      diffuseColor 0.333333 0.333333 0.498039
                      emissiveColor 0.815686 0.0431373 0.117647
                    }
                  }
                  geometry DEF leg1 Box {
                    size 0.0254 0.31 0.0254
                  }
                }
              ]
              name "hip2a"
              boundingObject USE leg1
              physics Physics {
              }
              linearVelocity -9.922746973973589e-06 1.2306896807590512e-05 -1.5568496486106914e-05
              angularVelocity -5.453991411081887e-05 3.225577535206849e-05 0.00015785196642830617
            }
          }
          Shape {
            appearance Appearance {
              material Material {
                diffuseColor 0.333333 0.666667 1
                emissiveColor 0.313725 0.666667 1
              }
            }
            geometry DEF servoMount1 Box {
              size 0.0254 0.0254 0.0254
            }
          }
        ]
        name "hip1a"
        boundingObject USE servoMount1
        physics Physics {
          density -1
          mass 1
        }
        linearVelocity -1.7705018804079486e-05 3.4168119419206276e-05 -1.880387638658032e-05
        angularVelocity -5.679037610107534e-05 3.407041430554489e-05 0.00016107298889391893
      }
    }
    DEF body_hip1_b HingeJoint {
      jointParameters HingeJointParameters {
        position -9.791196537169106e-07
        axis 0 1 0
        anchor 0.06 -0.06 0
        minStop -0.5
        maxStop 0.5
      }
      device [
        DEF hipx_b_pos_sensor PositionSensor {
          name "hipx_b_pos_sensor"
        }
        DEF h1b RotationalMotor {
          name "hipx_b"
        }
      ]
      endPoint Solid {
        translation 0.06 -0.06 0
        rotation 0.7071077811848892 0.7071057811836587 -2.105008737886098e-06 3.141589307660951
        children [
          DEF hip1_hip2 HingeJoint {
            jointParameters HingeJointParameters {
              position 0.44944326732577783
              axis 0 0 1
            }
            device [
              DEF hipy_b_pos_sensor PositionSensor {
                name "hipy_b_pos_sensor"
              }
              DEF h2 RotationalMotor {
                name "hipy_b"
              }
            ]
            endPoint Solid {
              translation -0.06516962376071714 0.13510336834767153 0.024999999999999984
              rotation 0 0 1 0.44944326732577816
              children [
                DEF leg1_leg2 HingeJoint {
                  jointParameters HingeJointParameters {
                    position -4.954537905832446e-06
                    axis 0 0 1
                    anchor 0 0.135 0
                  }
                  device [
                    DEF leg_b_pos_sensor PositionSensor {
                      name "leg_b_pos_sensor"
                    }
                    RotationalMotor {
                      name "leg_b"
                    }
                  ]
                  endPoint Solid {
                    translation 6.193172382126441e-07 0.2599999999984658 -0.025399999999999978
                    rotation 0 0 -0.9999999999999999 4.954540863055285e-06
                    children [
                      Shape {
                        appearance Appearance {
                          material Material {
                            diffuseColor 1 0.219608 0.92549
                            emissiveColor 0.666667 0 0.498039
                          }
                        }
                        geometry DEF leg2 Box {
                          size 0.0254 0.26 0.0254
                        }
                      }
                    ]
                    name "leg2"
                    boundingObject USE leg2
                    physics Physics {
                    }
                    linearVelocity -5.594951108082627e-05 -2.1931010655126843e-05 -3.075293142736849e-05
                    angularVelocity 8.43715348720393e-05 -3.824010538015967e-05 -0.0001950683127650608
                  }
                }
                Shape {
                  appearance Appearance {
                    material Material {
                      diffuseColor 0.333333 0.333333 0.498039
                      emissiveColor 0.815686 0.0431373 0.117647
                    }
                  }
                  geometry DEF leg1 Box {
                    size 0.0254 0.31 0.0254
                  }
                }
              ]
              name "hip2"
              boundingObject USE leg1
              physics Physics {
              }
              linearVelocity -2.9652929626619184e-05 2.713982887838784e-05 -2.442902730884025e-05
              angularVelocity 8.4053448602372e-05 -3.923330925581416e-05 -0.00019572533822770789
            }
          }
          Shape {
            appearance Appearance {
              material Material {
                diffuseColor 0.333333 0.666667 1
                emissiveColor 0.313725 0.666667 1
              }
            }
            geometry DEF servoMount1 Box {
              size 0.0254 0.0254 0.0254
            }
          }
        ]
        name "hip1(1)"
        boundingObject USE servoMount1
        physics Physics {
          density -1
          mass 1
        }
        linearVelocity -1.5880942831628885e-05 5.481608721288467e-05 -1.9343773198947645e-05
        angularVelocity -5.707791793096548e-05 -4.144036230377968e-05 0.00016227875458560474
      }
    }
    DEF body_hip1_c HingeJoint {
      jointParameters HingeJointParameters {
        position 1.0297873744292919e-05
        axis 0 1 0
        anchor 0 0.06 0.06
        minStop -0.5
        maxStop 0.5
      }
      device [
        DEF hipx_c_pos_sensor PositionSensor {
          name "hipx_c_pos_sensor"
        }
        DEF h1c RotationalMotor {
          name "hipx_c"
        }
      ]
      endPoint Solid {
        translation -4.074958040503545e-08 -0.06000059999999964 0.06000003438533074
        rotation 0.5773548072391648 0.5773508072691155 0.5773451930201959 2.0943956142246436
        children [
          DEF hip1_hip2 HingeJoint {
            jointParameters HingeJointParameters {
              position 0.4499662197413792
              axis 0 0 1
            }
            device [
              DEF hipy_c_pos_sensor PositionSensor {
                name "hipy_c_pos_sensor"
              }
              DEF h2 RotationalMotor {
                name "hipy_c"
                maxTorque 25
              }
            ]
            endPoint Solid {
              translation -0.06524026747906093 0.13506926926307314 0.024999999999999935
              rotation 0 0 1 0.44996621974137935
              children [
                DEF leg1_leg2 HingeJoint {
                  jointParameters HingeJointParameters {
                    position -3.4093088663311732e-06
                    axis 0 0 1
                    anchor 0 0.135 0
                  }
                  device [
                    DEF leg_c_pos_sensor PositionSensor {
                      name "leg_c_pos_sensor"
                    }
                    RotationalMotor {
                      name "leg_c"
                    }
                  ]
                  endPoint Solid {
                    translation 4.2616360828363143e-07 0.2599999999992733 -0.02539999999999987
                    rotation 0 0 -0.9999999999999999 3.409338789064289e-06
                    children [
                      Shape {
                        appearance Appearance {
                          material Material {
                            diffuseColor 1 0.219608 0.92549
                            emissiveColor 0.666667 0 0.498039
                          }
                        }
                        geometry DEF leg2 Box {
                          size 0.0254 0.26 0.0254
                        }
                      }
                    ]
                    name "leg2"
                    boundingObject USE leg2
                    physics Physics {
                    }
                    linearVelocity 1.7149607016579255e-05 4.0234461808450775e-05 1.3231230146742942e-05
                    angularVelocity -6.239578928214585e-05 9.712394012669542e-06 0.00016186843976501684
                  }
                }
                Shape {
                  appearance Appearance {
                    material Material {
                      diffuseColor 0.333333 0.333333 0.498039
                      emissiveColor 0.815686 0.0431373 0.117647
                    }
                  }
                  geometry DEF leg1 Box {
                    size 0.0254 0.31 0.0254
                  }
                }
              ]
              name "hip2"
              boundingObject USE leg1
              physics Physics {
              }
              linearVelocity -3.4021833086190708e-06 4.577023726740117e-05 1.9824363434837531e-07
              angularVelocity -6.13656256931611e-05 9.12931018322836e-06 0.00016197539163205076
            }
          }
          Shape {
            appearance Appearance {
              material Material {
                diffuseColor 0.333333 0.666667 1
                emissiveColor 0.313725 0.666667 1
              }
            }
            geometry DEF servoMount1 Box {
              size 0.0254 0.0254 0.0254
            }
          }
        ]
        name "hip1(2)"
        boundingObject USE servoMount1
        physics Physics {
          density -1
          mass 1
        }
        linearVelocity -1.5483365184891794e-05 4.25046021833424e-05 -9.049065012106895e-06
        angularVelocity -5.957981226406348e-05 8.124866642210182e-06 0.00016212204026400554
      }
    }
    DEF body_hip1_d HingeJoint {
      jointParameters HingeJointParameters {
        position 6.421352862656149e-06
        axis 0 1 0
        anchor 0 -0.06 -0.06
        minStop -0.5
        maxStop 0.5
      }
      device [
        DEF hipx_d_pos_sensor PositionSensor {
          name "hipx_d_pos_sensor"
        }
        DEF h1d RotationalMotor {
          name "hipx_d"
        }
      ]
      endPoint Solid {
        translation -2.0014476931000107e-13 -0.0600006 -0.06
        rotation -0.5773516999521702 -0.5773476999444898 0.5773514076636052 2.094391599485086
        children [
          DEF hip1_hip2 HingeJoint {
            jointParameters HingeJointParameters {
              position 0.44996210636590306
              axis 0 0 1
            }
            device [
              DEF hipy_d_pos_sensor PositionSensor {
                name "hipy_d_pos_sensor"
              }
              DEF h2 RotationalMotor {
                name "hipy_d"
                maxTorque 25
              }
            ]
            endPoint Solid {
              translation -0.06523971188788921 0.13506953761964663 0.024999999999999967
              rotation 0 0 1 0.44996210636590317
              children [
                DEF leg1_leg2 HingeJoint {
                  jointParameters HingeJointParameters {
                    position -3.870616437140484e-06
                    axis 0 0 1
                    anchor 0 0.135 0
                  }
                  device [
                    DEF leg_d_pos_sensor PositionSensor {
                      name "leg_d_pos_sensor"
                    }
                    DEF leg_d RotationalMotor {
                      name "leg_d"
                    }
                  ]
                  endPoint Solid {
                    translation 4.838270546344142e-07 0.25999999999906387 -0.025399999999999968
                    rotation 0 0 -0.9999999999999999 3.8706321942941554e-06
                    children [
                      Shape {
                        appearance Appearance {
                          material Material {
                            diffuseColor 1 0.219608 0.92549
                            emissiveColor 0.666667 0 0.498039
                          }
                        }
                        geometry DEF leg2 Box {
                          size 0.0254 0.26 0.0254
                        }
                      }
                    ]
                    name "leg2"
                    boundingObject USE leg2
                    physics Physics {
                    }
                    linearVelocity 1.820364552757541e-05 4.1755018294139365e-05 1.0804110763886587e-05
                    angularVelocity -6.340391497813695e-05 -4.556435408676306e-06 0.00016169911538839107
                  }
                }
                Shape {
                  appearance Appearance {
                    material Material {
                      diffuseColor 0.333333 0.333333 0.498039
                      emissiveColor 0.815686 0.0431373 0.117647
                    }
                  }
                  geometry DEF leg1 Box {
                    size 0.0254 0.31 0.0254
                  }
                }
              ]
              name "hip2"
              boundingObject USE leg1
              physics Physics {
              }
              linearVelocity -2.3242935532897057e-06 3.805068849339691e-05 -1.234364460939531e-06
              angularVelocity -6.187429606907308e-05 -3.81102039466051e-06 0.00016193875232650159
            }
          }
          Shape {
            appearance Appearance {
              material Material {
                diffuseColor 0.333333 0.666667 1
                emissiveColor 0.313725 0.666667 1
              }
            }
            geometry DEF servoMount1 Box {
              size 0.0254 0.0254 0.0254
            }
          }
        ]
        name "hip1(3)"
        boundingObject USE servoMount1
        physics Physics {
          density -1
          mass 1
        }
        linearVelocity -1.4761846968802672e-05 4.3053489762698404e-05 -9.86461386054316e-06
        angularVelocity -5.9592711859275324e-05 -2.412822994907706e-06 0.00016206317855068457
      }
    }
    DEF body Shape {
      appearance Appearance {
        material Material {
          ambientIntensity 0.3
          diffuseColor 1 1 0
          emissiveColor 1 0.666667 0
          shininess 1
        }
      }
      geometry Capsule {
        height 0.1
        radius 0.05
      }
    }
  ]
  name "chris"
  boundingObject USE body
  physics Physics {
    mass 1
  }
  controller "protocol2_controller"
  linearVelocity -2.5676418796720667e-05 4.363486461157606e-05 -1.7792825969650038e-05
  angularVelocity -5.8108758198114474e-05 2.930258160075405e-06 0.0001618758613138353
}
